add_mutation: Table column too large; cannot be more than 2**31 bytes.
Traceback (most recent call last):
  File "/u/home/j/jonmah/.local/lib/python3.6/site-packages/tskit/trees.py", line 1388, in load
    return TreeSequence.load(path)
  File "/u/home/j/jonmah/.local/lib/python3.6/site-packages/tskit/trees.py", line 1894, in load
    ts.load(str(path))
_tskit.FileFormatError: No such file or directory

The above exception was the direct cause of the following exception:

Traceback (most recent call last):
  File "AW_recap_python.py", line 19, in <module>
    main()
  File "AW_recap_python.py", line 11, in main
    ts = pyslim.load('../Data/AW_recap/seed_1.trees')
  File "/u/home/j/jonmah/.local/lib/python3.6/site-packages/pyslim/slim_tree_sequence.py", line 29, in load
    ts = SlimTreeSequence.load(path)
  File "/u/home/j/jonmah/.local/lib/python3.6/site-packages/pyslim/slim_tree_sequence.py", line 171, in load
    ts = tskit.load(path)
  File "/u/home/j/jonmah/.local/lib/python3.6/site-packages/tskit/trees.py", line 1390, in load
    formats.raise_hdf5_format_error(path, e)
  File "/u/home/j/jonmah/.local/lib/python3.6/site-packages/tskit/formats.py", line 259, in raise_hdf5_format_error
    raise exceptions.FileFormatError(str(original_exception)) from original_exception
_tskit.FileFormatError: No such file or directory
ERROR (SLiMSim::RunInitializeCallbacks): At least one mutation rate interval must be defined in an initialize() callback with initializeMutationRate().
grep: ../Data/AW_recap/seed_1.vcf: No such file or directory
grep: ../Data/AW_recap/seed_1.vcf: No such file or directory
DeprecationWarning: 'source deactivate' is deprecated. Use 'conda deactivate'.
2019-07-23 09:37:20,266 - INFO - Beginning execution of write_pops_file.py in directory /u/home/j/jonmah/lohmueller_lab/Scripts

2019-07-23 09:37:20,267 - INFO - Progress is being logged to ../Data/AW_recap/seed_1_syn_write_pops_log.log

2019-07-23 09:37:20,267 - INFO - Parsed the following arguments:
	num_ind_2 = 0
	outprefix = ../Data/AW_recap/seed_1_syn
	num_ind_1 = 15

2019-07-23 09:37:20,268 - INFO - Finished writing ../Data/AW_recap/seed_1_syn_pops_file.txt.
2019-07-23 09:37:20,366 - INFO - Beginning execution of write_pops_file.py in directory /u/home/j/jonmah/lohmueller_lab/Scripts

2019-07-23 09:37:20,366 - INFO - Progress is being logged to ../Data/AW_recap/seed_1_nonsyn_write_pops_log.log

2019-07-23 09:37:20,366 - INFO - Parsed the following arguments:
	num_ind_2 = 0
	outprefix = ../Data/AW_recap/seed_1_nonsyn
	num_ind_1 = 15

2019-07-23 09:37:20,368 - INFO - Finished writing ../Data/AW_recap/seed_1_nonsyn_pops_file.txt.
Traceback (most recent call last):
  File "easySFS.py", line 646, in <module>
    main()
  File "easySFS.py", line 590, in main
    indnames = get_inds_from_input(args.vcf_name, args.verbose)
  File "easySFS.py", line 410, in get_inds_from_input
    raise Exception("No sample names found in the input vcf. Check vcf file formatting.")
Exception: No sample names found in the input vcf. Check vcf file formatting.
Traceback (most recent call last):
  File "easySFS.py", line 646, in <module>
    main()
  File "easySFS.py", line 590, in main
    indnames = get_inds_from_input(args.vcf_name, args.verbose)
  File "easySFS.py", line 410, in get_inds_from_input
    raise Exception("No sample names found in the input vcf. Check vcf file formatting.")
Exception: No sample names found in the input vcf. Check vcf file formatting.
error: argument syn_input_sfs: invalid ExistingFile value: '../Data/AW_recap/seed_1_easySFS_output_syn/dadi/pop1.sfs'

