/work/UGE/8.6.4/n7454/job_scripts/361442: line 13: [0: command not found
2019-07-11 14:36:09,408 - INFO - Beginning execution of write_pops_file.py in directory /u/home/j/jonmah/lohmueller_lab/Scripts

2019-07-11 14:36:09,408 - INFO - Progress is being logged to ../Data/pilot_pipeline/seed_1_one_pop_log.log

2019-07-11 14:36:09,408 - INFO - Parsed the following arguments:
	num_ind_2 = 0
	outprefix = ../Data/pilot_pipeline/seed_1_one_pop
	num_ind_1 = 125

2019-07-11 14:36:09,416 - INFO - Finished writing ../Data/pilot_pipeline/seed_1_one_pop_pops_file.txt.
/u/home/j/jonmah/.conda/envs/jonmah_env/lib/python2.7/site-packages/dadi/Spectrum_mod.py:1641: FutureWarning: Using a non-tuple sequence for multidimensional indexing is deprecated; use `arr[tuple(seq)]` instead of `arr[seq]`. In the future this will be interpreted as an array index, `arr[np.array(seq)]`, which will result either in an error or a different result.
  contrib = _cached_projection(p_to,p_from,hits)[slices[pop_ii]]
/u/home/j/jonmah/.conda/envs/jonmah_env/lib/python2.7/site-packages/dadi/Numerics.py:138: FutureWarning: Using a non-tuple sequence for multidimensional indexing is deprecated; use `arr[tuple(seq)]` instead of `arr[seq]`. In the future this will be interpreted as an array index, `arr[np.array(seq)]`, which will result either in an error or a different result.
  return arr[reverse_slice]
Traceback (most recent call last):
  File "fitdadi_infer_DFE.py", line 157, in <module>
    main()
  File "fitdadi_infer_DFE.py", line 130, in main
    mp=True)
TypeError: __init__() got an unexpected keyword argument 'pts_1'
